[2024-07-19T09:09:22.274+0530] {local_task_job_runner.py:120} INFO - ::group::Pre task execution logs
[2024-07-19T09:09:22.284+0530] {taskinstance.py:2076} INFO - Dependencies all met for dep_context=non-requeueable deps ti=<TaskInstance: upload_a_batch_every_20_sec.send_email_on_failure scheduled__2024-07-19T00:18:40+00:00 [queued]>
[2024-07-19T09:09:22.289+0530] {taskinstance.py:2076} INFO - Dependencies all met for dep_context=requeueable deps ti=<TaskInstance: upload_a_batch_every_20_sec.send_email_on_failure scheduled__2024-07-19T00:18:40+00:00 [queued]>
[2024-07-19T09:09:22.289+0530] {taskinstance.py:2306} INFO - Starting attempt 2 of 2
[2024-07-19T09:09:22.296+0530] {taskinstance.py:2330} INFO - Executing <Task(EmailOperator): send_email_on_failure> on 2024-07-19 00:18:40+00:00
[2024-07-19T09:09:22.300+0530] {standard_task_runner.py:64} INFO - Started process 161349 to run task
[2024-07-19T09:09:22.302+0530] {standard_task_runner.py:90} INFO - Running: ['airflow', 'tasks', 'run', 'upload_a_batch_every_20_sec', 'send_email_on_failure', 'scheduled__2024-07-19T00:18:40+00:00', '--job-id', '323', '--raw', '--subdir', 'DAGS_FOLDER/car_insurance_policy_dag.py', '--cfg-path', '/tmp/tmpj2vltyiu']
[2024-07-19T09:09:22.302+0530] {standard_task_runner.py:91} INFO - Job 323: Subtask send_email_on_failure
[2024-07-19T09:09:22.327+0530] {task_command.py:426} INFO - Running <TaskInstance: upload_a_batch_every_20_sec.send_email_on_failure scheduled__2024-07-19T00:18:40+00:00 [running]> on host growlt245
[2024-07-19T09:09:22.356+0530] {taskinstance.py:2648} INFO - Exporting env vars: AIRFLOW_CTX_DAG_OWNER='airflow' AIRFLOW_CTX_DAG_ID='upload_a_batch_every_20_sec' AIRFLOW_CTX_TASK_ID='send_email_on_failure' AIRFLOW_CTX_EXECUTION_DATE='2024-07-19T00:18:40+00:00' AIRFLOW_CTX_TRY_NUMBER='2' AIRFLOW_CTX_DAG_RUN_ID='scheduled__2024-07-19T00:18:40+00:00'
[2024-07-19T09:09:22.357+0530] {taskinstance.py:430} INFO - ::endgroup::
[2024-07-19T09:09:22.360+0530] {base.py:84} INFO - Using connection ID 'smtp_default' for task execution.
[2024-07-19T09:09:22.360+0530] {email.py:271} INFO - Email alerting: attempt 1
[2024-07-19T09:09:24.453+0530] {taskinstance.py:441} INFO - ::group::Post task execution logs
[2024-07-19T09:09:24.455+0530] {taskinstance.py:2905} ERROR - Task failed with exception
Traceback (most recent call last):
  File "/home/growlt245/.local/lib/python3.10/site-packages/airflow/models/taskinstance.py", line 465, in _execute_task
    result = _execute_callable(context=context, **execute_callable_kwargs)
  File "/home/growlt245/.local/lib/python3.10/site-packages/airflow/models/taskinstance.py", line 432, in _execute_callable
    return execute_callable(context=context, **execute_callable_kwargs)
  File "/home/growlt245/.local/lib/python3.10/site-packages/airflow/models/baseoperator.py", line 401, in wrapper
    return func(self, *args, **kwargs)
  File "/home/growlt245/.local/lib/python3.10/site-packages/airflow/operators/email.py", line 79, in execute
    send_email(
  File "/home/growlt245/.local/lib/python3.10/site-packages/airflow/utils/email.py", line 80, in send_email
    return backend(
  File "/home/growlt245/.local/lib/python3.10/site-packages/airflow/utils/email.py", line 154, in send_email_smtp
    send_mime_email(e_from=mail_from, e_to=recipients, mime_msg=msg, conn_id=conn_id, dryrun=dryrun)
  File "/home/growlt245/.local/lib/python3.10/site-packages/airflow/utils/email.py", line 281, in send_mime_email
    smtp_conn.login(smtp_user, smtp_password)
  File "/usr/lib/python3.10/smtplib.py", line 750, in login
    raise last_exception
  File "/usr/lib/python3.10/smtplib.py", line 739, in login
    (code, resp) = self.auth(
  File "/usr/lib/python3.10/smtplib.py", line 662, in auth
    raise SMTPAuthenticationError(code, resp)
smtplib.SMTPAuthenticationError: (535, b'5.7.8 Username and Password not accepted. For more information, go to\n5.7.8  https://support.google.com/mail/?p=BadCredentials 41be03b00d2f7-79db56909c8sm330468a12.7 - gsmtp')
[2024-07-19T09:09:24.464+0530] {taskinstance.py:1206} INFO - Marking task as FAILED. dag_id=upload_a_batch_every_20_sec, task_id=send_email_on_failure, run_id=scheduled__2024-07-19T00:18:40+00:00, execution_date=20240719T001840, start_date=20240719T033922, end_date=20240719T033924
[2024-07-19T09:09:24.475+0530] {standard_task_runner.py:110} ERROR - Failed to execute job 323 for task send_email_on_failure ((535, b'5.7.8 Username and Password not accepted. For more information, go to\n5.7.8  https://support.google.com/mail/?p=BadCredentials 41be03b00d2f7-79db56909c8sm330468a12.7 - gsmtp'); 161349)
[2024-07-19T09:09:24.485+0530] {local_task_job_runner.py:243} INFO - Task exited with return code 1
[2024-07-19T09:09:24.497+0530] {taskinstance.py:3503} INFO - 0 downstream tasks scheduled from follow-on schedule check
[2024-07-19T09:09:24.498+0530] {local_task_job_runner.py:222} INFO - ::endgroup::
