[2024-07-18T15:26:07.056+0530] {local_task_job_runner.py:120} INFO - ::group::Pre task execution logs
[2024-07-18T15:26:07.060+0530] {taskinstance.py:2076} INFO - Dependencies all met for dep_context=non-requeueable deps ti=<TaskInstance: upload_a_batch_every_20_sec.process_and_upload_to_s3 scheduled__2024-07-18T00:20:40+00:00 [queued]>
[2024-07-18T15:26:07.062+0530] {taskinstance.py:2076} INFO - Dependencies all met for dep_context=requeueable deps ti=<TaskInstance: upload_a_batch_every_20_sec.process_and_upload_to_s3 scheduled__2024-07-18T00:20:40+00:00 [queued]>
[2024-07-18T15:26:07.062+0530] {taskinstance.py:2306} INFO - Starting attempt 2 of 2
[2024-07-18T15:26:07.068+0530] {taskinstance.py:2330} INFO - Executing <Task(PythonOperator): process_and_upload_to_s3> on 2024-07-18 00:20:40+00:00
[2024-07-18T15:26:07.072+0530] {standard_task_runner.py:64} INFO - Started process 52597 to run task
[2024-07-18T15:26:07.073+0530] {standard_task_runner.py:90} INFO - Running: ['airflow', 'tasks', 'run', 'upload_a_batch_every_20_sec', 'process_and_upload_to_s3', 'scheduled__2024-07-18T00:20:40+00:00', '--job-id', '84', '--raw', '--subdir', 'DAGS_FOLDER/car_insurance_policy_dag.py', '--cfg-path', '/tmp/tmproi5isvl']
[2024-07-18T15:26:07.074+0530] {standard_task_runner.py:91} INFO - Job 84: Subtask process_and_upload_to_s3
[2024-07-18T15:26:07.090+0530] {task_command.py:426} INFO - Running <TaskInstance: upload_a_batch_every_20_sec.process_and_upload_to_s3 scheduled__2024-07-18T00:20:40+00:00 [running]> on host growlt245
[2024-07-18T15:26:07.116+0530] {taskinstance.py:2648} INFO - Exporting env vars: AIRFLOW_CTX_DAG_OWNER='airflow' AIRFLOW_CTX_DAG_ID='upload_a_batch_every_20_sec' AIRFLOW_CTX_TASK_ID='process_and_upload_to_s3' AIRFLOW_CTX_EXECUTION_DATE='2024-07-18T00:20:40+00:00' AIRFLOW_CTX_TRY_NUMBER='2' AIRFLOW_CTX_DAG_RUN_ID='scheduled__2024-07-18T00:20:40+00:00'
[2024-07-18T15:26:07.116+0530] {taskinstance.py:430} INFO - ::endgroup::
[2024-07-18T15:26:07.116+0530] {logging_mixin.py:188} INFO - Current working directory: /home/growlt245
[2024-07-18T15:26:07.117+0530] {car_insurance_policy_dag.py:94} ERROR - Error in process_and_upload: [Errno 2] No such file or directory: '/home/growlt245/airflow/Amended_Insurance_Product_purchase_dataset.csv'
[2024-07-18T15:26:07.117+0530] {taskinstance.py:441} INFO - ::group::Post task execution logs
[2024-07-18T15:26:07.117+0530] {taskinstance.py:2905} ERROR - Task failed with exception
Traceback (most recent call last):
  File "/home/growlt245/.local/lib/python3.10/site-packages/airflow/models/taskinstance.py", line 465, in _execute_task
    result = _execute_callable(context=context, **execute_callable_kwargs)
  File "/home/growlt245/.local/lib/python3.10/site-packages/airflow/models/taskinstance.py", line 432, in _execute_callable
    return execute_callable(context=context, **execute_callable_kwargs)
  File "/home/growlt245/.local/lib/python3.10/site-packages/airflow/models/baseoperator.py", line 401, in wrapper
    return func(self, *args, **kwargs)
  File "/home/growlt245/.local/lib/python3.10/site-packages/airflow/operators/python.py", line 235, in execute
    return_value = self.execute_callable()
  File "/home/growlt245/.local/lib/python3.10/site-packages/airflow/operators/python.py", line 252, in execute_callable
    return self.python_callable(*self.op_args, **self.op_kwargs)
  File "/home/growlt245/airflow/dags/car_insurance_policy_dag.py", line 47, in process_and_upload
    df = pd.read_csv(LOCAL_CSV_FILE)
  File "/usr/local/lib/python3.10/dist-packages/pandas/io/parsers/readers.py", line 1024, in read_csv
    return _read(filepath_or_buffer, kwds)
  File "/usr/local/lib/python3.10/dist-packages/pandas/io/parsers/readers.py", line 618, in _read
    parser = TextFileReader(filepath_or_buffer, **kwds)
  File "/usr/local/lib/python3.10/dist-packages/pandas/io/parsers/readers.py", line 1618, in __init__
    self._engine = self._make_engine(f, self.engine)
  File "/usr/local/lib/python3.10/dist-packages/pandas/io/parsers/readers.py", line 1878, in _make_engine
    self.handles = get_handle(
  File "/usr/local/lib/python3.10/dist-packages/pandas/io/common.py", line 873, in get_handle
    handle = open(
FileNotFoundError: [Errno 2] No such file or directory: '/home/growlt245/airflow/Amended_Insurance_Product_purchase_dataset.csv'
[2024-07-18T15:26:07.119+0530] {taskinstance.py:1206} INFO - Marking task as FAILED. dag_id=upload_a_batch_every_20_sec, task_id=process_and_upload_to_s3, run_id=scheduled__2024-07-18T00:20:40+00:00, execution_date=20240718T002040, start_date=20240718T095607, end_date=20240718T095607
[2024-07-18T15:26:07.120+0530] {baseoperator.py:400} WARNING - EmailOperator.execute cannot be called outside TaskInstance!
[2024-07-18T15:26:07.122+0530] {base.py:84} INFO - Using connection ID 'smtp_default' for task execution.
[2024-07-18T15:26:07.122+0530] {email.py:271} INFO - Email alerting: attempt 1
[2024-07-18T15:26:10.289+0530] {taskinstance.py:1182} ERROR - Error when executing notify_email callback
Traceback (most recent call last):
  File "/home/growlt245/.local/lib/python3.10/site-packages/airflow/models/taskinstance.py", line 2479, in _run_raw_task
    self._execute_task_with_callbacks(context, test_mode, session=session)
  File "/home/growlt245/.local/lib/python3.10/site-packages/airflow/models/taskinstance.py", line 2676, in _execute_task_with_callbacks
    result = self._execute_task(context, task_orig)
  File "/home/growlt245/.local/lib/python3.10/site-packages/airflow/models/taskinstance.py", line 2701, in _execute_task
    return _execute_task(self, context, task_orig)
  File "/home/growlt245/.local/lib/python3.10/site-packages/airflow/models/taskinstance.py", line 465, in _execute_task
    result = _execute_callable(context=context, **execute_callable_kwargs)
  File "/home/growlt245/.local/lib/python3.10/site-packages/airflow/models/taskinstance.py", line 432, in _execute_callable
    return execute_callable(context=context, **execute_callable_kwargs)
  File "/home/growlt245/.local/lib/python3.10/site-packages/airflow/models/baseoperator.py", line 401, in wrapper
    return func(self, *args, **kwargs)
  File "/home/growlt245/.local/lib/python3.10/site-packages/airflow/operators/python.py", line 235, in execute
    return_value = self.execute_callable()
  File "/home/growlt245/.local/lib/python3.10/site-packages/airflow/operators/python.py", line 252, in execute_callable
    return self.python_callable(*self.op_args, **self.op_kwargs)
  File "/home/growlt245/airflow/dags/car_insurance_policy_dag.py", line 47, in process_and_upload
    df = pd.read_csv(LOCAL_CSV_FILE)
  File "/usr/local/lib/python3.10/dist-packages/pandas/io/parsers/readers.py", line 1024, in read_csv
    return _read(filepath_or_buffer, kwds)
  File "/usr/local/lib/python3.10/dist-packages/pandas/io/parsers/readers.py", line 618, in _read
    parser = TextFileReader(filepath_or_buffer, **kwds)
  File "/usr/local/lib/python3.10/dist-packages/pandas/io/parsers/readers.py", line 1618, in __init__
    self._engine = self._make_engine(f, self.engine)
  File "/usr/local/lib/python3.10/dist-packages/pandas/io/parsers/readers.py", line 1878, in _make_engine
    self.handles = get_handle(
  File "/usr/local/lib/python3.10/dist-packages/pandas/io/common.py", line 873, in get_handle
    handle = open(
FileNotFoundError: [Errno 2] No such file or directory: '/home/growlt245/airflow/Amended_Insurance_Product_purchase_dataset.csv'

During handling of the above exception, another exception occurred:

Traceback (most recent call last):
  File "/home/growlt245/.local/lib/python3.10/site-packages/airflow/models/taskinstance.py", line 1179, in _run_finished_callback
    callback(context)
  File "/home/growlt245/airflow/dags/car_insurance_policy_dag.py", line 118, in notify_email
    return email_operator.execute(context)
  File "/home/growlt245/.local/lib/python3.10/site-packages/airflow/models/baseoperator.py", line 401, in wrapper
    return func(self, *args, **kwargs)
  File "/home/growlt245/.local/lib/python3.10/site-packages/airflow/operators/email.py", line 79, in execute
    send_email(
  File "/home/growlt245/.local/lib/python3.10/site-packages/airflow/utils/email.py", line 80, in send_email
    return backend(
  File "/home/growlt245/.local/lib/python3.10/site-packages/airflow/utils/email.py", line 154, in send_email_smtp
    send_mime_email(e_from=mail_from, e_to=recipients, mime_msg=msg, conn_id=conn_id, dryrun=dryrun)
  File "/home/growlt245/.local/lib/python3.10/site-packages/airflow/utils/email.py", line 281, in send_mime_email
    smtp_conn.login(smtp_user, smtp_password)
  File "/usr/lib/python3.10/smtplib.py", line 750, in login
    raise last_exception
  File "/usr/lib/python3.10/smtplib.py", line 739, in login
    (code, resp) = self.auth(
  File "/usr/lib/python3.10/smtplib.py", line 662, in auth
    raise SMTPAuthenticationError(code, resp)
smtplib.SMTPAuthenticationError: (535, b'5.7.8 Username and Password not accepted. For more information, go to\n5.7.8  https://support.google.com/mail/?p=BadCredentials 98e67ed59e1d1-2cb77adcf7asm207090a91.44 - gsmtp')
[2024-07-18T15:26:10.308+0530] {standard_task_runner.py:110} ERROR - Failed to execute job 84 for task process_and_upload_to_s3 ([Errno 2] No such file or directory: '/home/growlt245/airflow/Amended_Insurance_Product_purchase_dataset.csv'; 52597)
[2024-07-18T15:26:10.348+0530] {local_task_job_runner.py:243} INFO - Task exited with return code 1
[2024-07-18T15:26:10.365+0530] {taskinstance.py:3503} INFO - 0 downstream tasks scheduled from follow-on schedule check
[2024-07-18T15:26:10.366+0530] {local_task_job_runner.py:222} INFO - ::endgroup::
